<?xml version="1.0" encoding="utf-8"?>
<!-- This URDF was automatically created by SolidWorks to URDF Exporter! Originally created by Stephen Brawner (brawner@gmail.com) 
     Commit Version: 1.6.0-1-g15f4949  Build Version: 1.6.7594.29634
     For more information, please see http://wiki.ros.org/sw_urdf_exporter -->
<robot name="rover" xmlns:xacro="http://ros.org/wiki/xacro">
  <xacro:include filename="$(find rover_gazebo)/xacro/rover.gazebo.xacro"/>
  <!-- <link name="odom" />

	<joint name="base_joint" type="fixed">
		<parent link="odom"/>
		<child link="base_link"/>
	</joint> -->

  <link
    name="base_link">
    <inertial>
      <origin
        xyz="0.0562591525803034 5.21904025701792E-05 0.0"
        rpy="0 0 0" />
      <mass
        value="1.0" />
      <inertia
        ixx="-0.010062"
        ixy="-0.189732"
        ixz="0.981784"
        iyy="0.044374"
        iyz="-0.001663"
        izz="-0.189991" />
    </inertial>
    <visual>
      <origin
        xyz="0 0 0"
        rpy="0 0 0" />
      <geometry>
        <mesh filename="package://rover/meshes/resize_rover/devide_rover/body.dae"/>
      </geometry>
      <material
        name="">
        <color
          rgba="0.792156862745098 0.819607843137255 0.933333333333333 1" />
      </material>
    </visual>
    <collision>
      <origin
        xyz="0 0 0"
        rpy="0 0 0" />
      <geometry>
        <mesh filename="package://rover/meshes/resize_rover/devide_rover/body.dae"/>
      </geometry>
    </collision>
  </link>
  <link name='front_left_temp_link'>
		<inertial>
            <origin xyz="0 0 0" rpy="0 0 0"/>
            <mass value="0.02" />
            <inertia ixx="2.61666666667e-05" ixy="0.0" ixz="0.0" iyy="2.61666666667e-05" iyz="0.0" izz="3.6e-05"/>
        </inertial>
        <collision>
            <origin rpy="0 0 0" xyz="0 0 0"/>
            <geometry>
                <cylinder radius="0.00000001" length="0.00000001"/>
            </geometry>
        </collision>
		<visual>
            <origin rpy="0 0 0" xyz="0 0 0"/>
            <geometry>
                <cylinder radius="0.00000001" length="0.00000001"/>
            </geometry>
        </visual>
	</link>
  <joint
  name="ffl_temp_joint"
  type="fixed">
   <origin xyz="0.10365 -0.49846 0.071114" rpy="0 0 0"/>
  <parent
    link="base_link" />
  <child
    link="front_left_temp_link" />
  <axis
    xyz="1 0 0" />
</joint>
  <link
    name="front_left_suspension_link">
    <inertial>
      <origin
        xyz="-0.0078125 1.2678E-05 0.060941"
        rpy="0 0 0" />
      <mass
        value="0.30421" />
      <inertia
        ixx="0.00022406"
        ixy="-5.3036E-09"
        ixz="-1.2289E-08"
        iyy="0.00021285"
        iyz="-2.5969E-08"
        izz="0.00027948" />
    </inertial>
    <visual>
      <origin
        xyz="0 0 0"
        rpy="0 0 0" />
      <geometry>
        <mesh
          filename="package://rover/meshes/resize_rover/devide_rover/FRLH_Suspension.dae" />
      </geometry>
      <material
        name="">
        <color
          rgba="0.79216 0.81961 0.93333 1" />
      </material>
    </visual>
    <collision>
      <origin
        xyz="0 0 0"
        rpy="0 0 0" />
      <geometry>
        <mesh
          filename="package://rover/meshes/resize_rover/devide_rover/FRLH_Suspension.dae" />
      </geometry>
    </collision>
  </link>
  <joint
    name="ffl_suspension_joint"
    type="revolute">
     <origin xyz="0 0 0" rpy="0 0 0"/>
    <parent
      link="front_left_temp_link" />
    <child
      link="front_left_suspension_link" />
    <axis
      xyz="1 0 0" />
    <limit effort="5" velocity="6.28"  lower="-2.1" upper="2.1" />
  </joint>
  <link name='front_left_temp_link2'>
		<inertial>
            <origin xyz="0 0 0" rpy="0 0 0"/>
            <mass value="0.02" />
            <inertia ixx="2.61666666667e-05" ixy="0.0" ixz="0.0" iyy="2.61666666667e-05" iyz="0.0" izz="3.6e-05"/>
        </inertial>
        <collision>
            <origin rpy="0 0 0" xyz="0 0 0"/>
            <geometry>
                <cylinder radius="0.00000001" length="0.00000001"/>
            </geometry>
        </collision>
		<visual>
            <origin rpy="0 0 0" xyz="0 0 0"/>
            <geometry>
                <cylinder radius="0.00000001" length="0.00000001"/>
            </geometry>
        </visual>
	</link>
  <joint
  name="ffl_temp_joint2"
  type="fixed">
   <origin xyz="-0.061936 -0.2751 -0.048216" rpy="0 0 0"/>
  <parent
    link="front_left_suspension_link" />
  <child
    link="front_left_temp_link2" />
  <axis
    xyz="1 0 0" />
</joint>
  <link
    name="front_left_steering_link">
    <inertial>
      <origin
        xyz="-0.0078125 1.2678E-05 0.060941"
        rpy="0 0 0" />
      <mass
        value="0.30421" />
      <inertia
        ixx="0.00022406"
        ixy="-5.3036E-09"
        ixz="-1.2289E-08"
        iyy="0.00021285"
        iyz="-2.5969E-08"
        izz="0.00027948" />
    </inertial>
    <visual>
      <origin
        xyz="0 0 0"
        rpy="0 0 0" />
      <geometry>
        <mesh
          filename="package://rover/meshes/resize_rover/devide_rover/FRLH_Steering.dae" />
      </geometry>
      <material
        name="">
        <color
          rgba="0.79216 0.81961 0.93333 1" />
      </material>
    </visual>
    <collision>
      <origin
        xyz="0 0 0"
        rpy="0 0 0" />
      <geometry>
        <mesh
          filename="package://rover/meshes/resize_rover/devide_rover/FRLH_Steering.dae" />
      </geometry>
    </collision>
  </link>
  <joint
    name="front_left_steering_joint"
    type="revolute">
     <origin xyz="0 0 0" rpy="0 0 0"/>
    <parent
      link="front_left_temp_link2" />
    <child
      link="front_left_steering_link" />
    <axis
      xyz="0 0 1" />
    <limit effort="5" velocity="6.28"  lower="-2.1" upper="2.1" />
  </joint>
  <link name='front_left_temp_link3'>
		<inertial>
            <origin xyz="0 0 0" rpy="0 0 0"/>
            <mass value="0.02" />
            <inertia ixx="2.61666666667e-05" ixy="0.0" ixz="0.0" iyy="2.61666666667e-05" iyz="0.0" izz="3.6e-05"/>
        </inertial>
        <collision>
            <origin rpy="0 0 0" xyz="0 0 0"/>
            <geometry>
                <cylinder radius="0.00000001" length="0.00000001"/>
            </geometry>
        </collision>
		<visual>
            <origin rpy="0 0 0" xyz="0 0 0"/>
            <geometry>
                <cylinder radius="0.00000001" length="0.00000001"/>
            </geometry>
        </visual>
	</link>
  <joint
  name="ffl_temp_joint3"
  type="fixed">
   <origin xyz="-0.0541 -0.0657 -0.0259" rpy="0 0 0"/>
  <parent
    link="front_left_steering_link" />
  <child
    link="front_left_temp_link3" />
  <axis
    xyz="1 0 0" />
</joint>
  <link
    name="ffl_wheel_link">
    <inertial>
      <origin
        xyz="-0.0016559 2.498E-05 -1.1185E-05"
        rpy="0 0 0" />
      <mass
        value="1.1363" />
      <inertia
        ixx="0.0049366"
        ixy="-9.2744E-07"
        ixz="2.0492E-07"
        iyy="0.002578"
        iyz="9.052E-08"
        izz="0.0025791" />
    </inertial>
    <visual>
      <origin
        xyz="0 0 0"
        rpy="0 0 0" />
      <geometry>
        <mesh
          filename="package://rover/meshes/resize_rover/devide_rover/FRLH_Wheel.dae" />
      </geometry>
      <material
        name="">
        <color
          rgba="0.79216 0.81961 0.93333 1" />
      </material>
    </visual>
    <collision>
      <origin
        xyz="0 0 0"
        rpy="0 0 0" />
      <geometry>
        <mesh
          filename="package://rover/meshes/resize_rover/devide_rover/FRLH_Wheel.dae" />
      </geometry>
    </collision>
  </link>
  <joint
    name="ffl_wheel_joint"
    type="continuous">
   <origin xyz="0 0 0" rpy="0 0 0"/>
    <parent
      link="front_left_temp_link3" />
    <child
      link="ffl_wheel_link" />
    <axis
      xyz="0 1 0" />
    <limit effort="1.5" velocity="20"/>
  </joint>
  <link name='front_right_temp_link'>
		<inertial>
            <origin xyz="0 0 0" rpy="0 0 0"/>
            <mass value="0.02" />
            <inertia ixx="2.61666666667e-05" ixy="0.0" ixz="0.0" iyy="2.61666666667e-05" iyz="0.0" izz="3.6e-05"/>
        </inertial>
        <collision>
            <origin rpy="0 0 0" xyz="0 0 0"/>
            <geometry>
                <cylinder radius="0.00000001" length="0.00000001"/>
            </geometry>
        </collision>
		<visual>
            <origin rpy="0 0 0" xyz="0 0 0"/>
            <geometry>
                <cylinder radius="0.00000001" length="0.00000001"/>
            </geometry>
        </visual>
	</link>
  <joint
  name="ffr_temp_joint"
  type="fixed">
   <origin xyz="0.10427 0.49792 0.072906" rpy="0 0 0"/>
  <parent
    link="base_link" />
  <child
    link="front_right_temp_link" />
  <axis
    xyz="1 0 0" />
</joint>
  <link
  name="front_right_suspension_link">
  <inertial>
    <origin
      xyz="-0.0078125 1.2678E-05 0.060941"
      rpy="0 0 0" />
    <mass
      value="0.30421" />
    <inertia
      ixx="0.00022406"
      ixy="-5.3036E-09"
      ixz="-1.2289E-08"
      iyy="0.00021285"
      iyz="-2.5969E-08"
      izz="0.00027948" />
  </inertial>
  <visual>
    <origin
      xyz="0 0 0"
      rpy="0 0 0" />
    <geometry>
      <mesh
        filename="package://rover/meshes/resize_rover/devide_rover/FRRH_Suspension.dae" />
    </geometry>
    <material
      name="">
      <color
        rgba="0.79216 0.81961 0.93333 1" />
    </material>
  </visual>
  <collision>
    <origin
      xyz="0 0 0"
      rpy="0 0 0" />
    <geometry>
      <mesh
        filename="package://rover/meshes/resize_rover/devide_rover/FRRH_Suspension.dae" />
    </geometry>
  </collision>
</link>
<joint
  name="ffr_suspension_joint"
  type="revolute">
   <origin xyz="0 0 0" rpy="0 0 0"/>
  <parent
    link="front_right_temp_link" />
  <child
    link="front_right_suspension_link" />
  <axis
    xyz="1 0 0" />
  <limit effort="5" velocity="6.28"  lower="-2.1" upper="2.1" />
</joint>
<link name='front_right_temp_link2'>
  <inertial>
          <origin xyz="0 0 0" rpy="0 0 0"/>
          <mass value="0.02" />
          <inertia ixx="2.61666666667e-05" ixy="0.0" ixz="0.0" iyy="2.61666666667e-05" iyz="0.0" izz="3.6e-05"/>
      </inertial>
      <collision>
          <origin rpy="0 0 0" xyz="0 0 0"/>
          <geometry>
              <cylinder radius="0.00000001" length="0.00000001"/>
          </geometry>
      </collision>
  <visual>
          <origin rpy="0 0 0" xyz="0 0 0"/>
          <geometry>
              <cylinder radius="0.00000001" length="0.00000001"/>
          </geometry>
      </visual>
</link>
<joint
name="ffr_temp_joint2"
type="fixed">
 <origin xyz="-0.061936 0.27526 -0.05453" rpy="0 0 0"/>
<parent
  link="front_right_suspension_link" />
<child
  link="front_right_temp_link2" />
<axis
  xyz="1 0 0" />
</joint>
  <link
    name="front_right_steering_link">
    <inertial>
      <origin
        xyz="0.0078149 5.813E-06 0.060941"
        rpy="0 0 0" />
      <mass
        value="0.30422" />
      <inertia
        ixx="0.00022406"
        ixy="-6.6817E-09"
        ixz="7.4999E-08"
        iyy="0.00021285"
        iyz="-1.9079E-08"
        izz="0.00027948" />
    </inertial>
    <visual>
      <origin
        xyz="0 0 0"
        rpy="0 0 0" />
      <geometry>
        <mesh
          filename="package://rover/meshes/resize_rover/devide_rover/FRRH_Steering.dae" />
      </geometry>
      <material
        name="">
        <color
          rgba="0.79216 0.81961 0.93333 1" />
      </material>
    </visual>
    <collision>
      <origin
        xyz="0 0 0"
        rpy="0 0 0" />
      <geometry>
        <mesh
          filename="package://rover/meshes/resize_rover/devide_rover/FRRH_Steering.dae" />
      </geometry>
    </collision>
  </link>
  <joint
    name="front_right_steering_joint"
    type="revolute">
    <origin xyz="0 0 0" rpy="0 0 0"/>
    <parent
      link="front_right_temp_link2" />
    <child
      link="front_right_steering_link" />
    <axis
      xyz="0 0 1" />
    <limit effort="5" velocity="6.28"  lower="-2.1" upper="2.1" />
  </joint>
  <link name='front_right_temp_link3'>
		<inertial>
            <origin xyz="0 0 0" rpy="0 0 0"/>
            <mass value="0.02" />
            <inertia ixx="2.61666666667e-05" ixy="0.0" ixz="0.0" iyy="2.61666666667e-05" iyz="0.0" izz="3.6e-05"/>
        </inertial>
        <collision>
            <origin rpy="0 0 0" xyz="0 0 0"/>
            <geometry>
                <cylinder radius="0.00000001" length="0.00000001"/>
            </geometry>
        </collision>
		<visual>
            <origin rpy="0 0 0" xyz="0 0 0"/>
            <geometry>
                <cylinder radius="0.00000001" length="0.00000001"/>
            </geometry>
        </visual>
	</link>
  <joint
  name="ffr_temp_joint3"
  type="fixed">
   <origin xyz="-0.0023 0.0658 -0.0255" rpy="0 0 0"/>
  <parent
    link="front_right_steering_link" />
  <child
    link="front_right_temp_link3" />
  <axis
    xyz="1 0 0" />
</joint>
  <link
    name="ffr_wheel_link">
    <inertial>
      <origin
        xyz="0.0016472 -1.6563E-05 2.7857E-05"
        rpy="0 0 0" />
      <mass
        value="1.1364" />
      <inertia
        ixx="0.0049371"
        ixy="-9.2722E-07"
        ixz="-1.9886E-07"
        iyy="0.0025793"
        iyz="-6.7378E-08"
        izz="0.0025805" />
    </inertial>
    <visual>
      <origin
        xyz="0 0 0"
        rpy="0 0 0" />
      <geometry>
        <mesh
          filename="package://rover/meshes/resize_rover/devide_rover/FRRH_Wheel.dae" />
      </geometry>
      <material
        name="">
        <color
          rgba="0.79216 0.81961 0.93333 1" />
      </material>
    </visual>
    <collision>
      <origin
        xyz="0 0 0"
        rpy="0 0 0" />
      <geometry>
        <mesh
          filename="package://rover/meshes/resize_rover/devide_rover/FRRH_Wheel.dae" />
      </geometry>
    </collision>
  </link>
  <joint
    name="ffr_wheel_joint"
    type="continuous">
    <origin xyz="-0.0023 0.0658 -0.0255" rpy="0 0 0"/>
    <parent
      link="front_right_temp_link3" />
    <child
      link="ffr_wheel_link" />
    <axis
      xyz="0 1 0" />
    <limit effort="1.5" velocity="20"/>
  </joint>
  <link name='rear_left_temp_link'>
		<inertial>
            <origin xyz="0 0 0" rpy="0 0 0"/>
            <mass value="0.02" />
            <inertia ixx="2.61666666667e-05" ixy="0.0" ixz="0.0" iyy="2.61666666667e-05" iyz="0.0" izz="3.6e-05"/>
        </inertial>
        <collision>
            <origin rpy="0 0 0" xyz="0 0 0"/>
            <geometry>
                <cylinder radius="0.00000001" length="0.00000001"/>
            </geometry>
        </collision>
		<visual>
            <origin rpy="0 0 0" xyz="0 0 0"/>
            <geometry>
                <cylinder radius="0.00000001" length="0.00000001"/>
            </geometry>
        </visual>
	</link>
  <joint
  name="rfl_temp_joint"
  type="fixed">
   <origin xyz="1.3343 -0.49919 0.072726" rpy="0 0 0"/>
  <parent
    link="base_link" />
  <child
    link="rear_left_temp_link" />
  <axis
    xyz="1 0 0" />
</joint>
  <link
  name="rear_left_suspension_link">
  <inertial>
    <origin
      xyz="-0.0078125 1.2678E-05 0.060941"
      rpy="0 0 0" />
    <mass
      value="0.30421" />
    <inertia
      ixx="0.00022406"
      ixy="-5.3036E-09"
      ixz="-1.2289E-08"
      iyy="0.00021285"
      iyz="-2.5969E-08"
      izz="0.00027948" />
  </inertial>
  <visual>
    <origin
      xyz="0 0 0"
      rpy="0 0 0" />
    <geometry>
      <mesh
        filename="package://rover/meshes/resize_rover/devide_rover/RRLH_Suspension.dae" />
    </geometry>
    <material
      name="">
      <color
        rgba="0.79216 0.81961 0.93333 1" />
    </material>
  </visual>
  <collision>
    <origin
      xyz="0 0 0"
      rpy="0 0 0" />
    <geometry>
      <mesh
        filename="package://rover/meshes/resize_rover/devide_rover/RRLH_Suspension.dae" />
    </geometry>
  </collision>
</link>
<joint
  name="rfl_suspension_joint"
  type="revolute">
   <origin xyz="0 0 0" rpy="0 0 0"/>
  <parent
    link="rear_left_temp_link" />
  <child
    link="rear_left_suspension_link" />
  <axis
    xyz="1 0 0" />
  <limit effort="5" velocity="6.28"  lower="-2.1" upper="2.1" />
</joint>
<link name='rear_left_temp_link2'>
  <inertial>
          <origin xyz="0 0 0" rpy="0 0 0"/>
          <mass value="0.02" />
          <inertia ixx="2.61666666667e-05" ixy="0.0" ixz="0.0" iyy="2.61666666667e-05" iyz="0.0" izz="3.6e-05"/>
      </inertial>
      <collision>
          <origin rpy="0 0 0" xyz="0 0 0"/>
          <geometry>
              <cylinder radius="0.00000001" length="0.00000001"/>
          </geometry>
      </collision>
  <visual>
          <origin rpy="0 0 0" xyz="0 0 0"/>
          <geometry>
              <cylinder radius="0.00000001" length="0.00000001"/>
          </geometry>
      </visual>
</link>
<joint
name="rfl_temp_joint2"
type="fixed">
 <origin xyz="0.0638 -0.2743 -0.054" rpy="0 0 0"/>
<parent
  link="rear_left_suspension_link" />
<child
  link="rear_left_temp_link2" />
<axis
  xyz="1 0 0" />
</joint>
  <link
    name="rear_left_steering_link">
    <inertial>
      <origin
        xyz="-0.0079979 9.6737E-06 0.062261"
        rpy="0 0 0" />
      <mass
        value="0.2968" />
      <inertia
        ixx="0.00021788"
        ixy="-5.0547E-08"
        ixz="-7.6105E-09"
        iyy="0.00020665"
        iyz="1.9139E-08"
        izz="0.00026712" />
    </inertial>
    <visual>
      <origin
        xyz="0 0 0"
        rpy="0 0 0" />
      <geometry>
        <mesh
          filename="package://rover/meshes/resize_rover/devide_rover/RRLH_Steering.dae" />
      </geometry>
      <material
        name="">
        <color
          rgba="0.79216 0.81961 0.93333 1" />
      </material>
    </visual>
    <collision>
      <origin
        xyz="0 0 0"
        rpy="0 0 0" />
      <geometry>
        <mesh
          filename="package://rover/meshes/resize_rover/devide_rover/RRLH_Steering.dae" />
      </geometry>
    </collision>
  </link>
  <joint
    name="rear_left_steering_joint"
    type="revolute">
    <origin xyz="0 0 0" rpy="0 0 0" />
    <parent
      link="rear_left_temp_link2" />
    <child
      link="rear_left_steering_link" />
    <axis
      xyz="0 0 1" />
    <limit effort="5" velocity="6.28"  lower="-2.1" upper="2.1" />
  </joint>
  <link name='rear_left_temp_link3'>
		<inertial>
            <origin xyz="0 0 0" rpy="0 0 0"/>
            <mass value="0.02" />
            <inertia ixx="2.61666666667e-05" ixy="0.0" ixz="0.0" iyy="2.61666666667e-05" iyz="0.0" izz="3.6e-05"/>
        </inertial>
        <collision>
            <origin rpy="0 0 0" xyz="0 0 0"/>
            <geometry>
                <cylinder radius="0.00000001" length="0.00000001"/>
            </geometry>
        </collision>
		<visual>
            <origin rpy="0 0 0" xyz="0 0 0"/>
            <geometry>
                <cylinder radius="0.00000001" length="0.00000001"/>
            </geometry>
        </visual>
	</link>
  <joint
  name="rfl_temp_joint3"
  type="fixed">
   <origin xyz="-0.0137 -0.0657 -0.0259" rpy="0 0 0"/>
  <parent
    link="rear_left_steering_link" />
  <child
    link="rear_left_temp_link3" />
  <axis
    xyz="1 0 0" />
</joint>
  <link
    name="rfl_wheel_link">
    <inertial>
      <origin
        xyz="-0.0016588 2.035E-05 8.7225E-06"
        rpy="0 0 0" />
      <mass
        value="1.1361" />
      <inertia
        ixx="0.0049373"
        ixy="-9.2167E-07"
        ixz="1.9763E-07"
        iyy="0.0025788"
        iyz="3.731E-07"
        izz="0.002579" />
    </inertial>
    <visual>
      <origin
        xyz="0 0 0"
        rpy="0 0 0" />
      <geometry>
        <mesh
          filename="package://rover/meshes/resize_rover/devide_rover/RRLH_Wheel.dae" />
      </geometry>
      <material
        name="">
        <color
          rgba="0.79216 0.81961 0.93333 1" />
      </material>
    </visual>
    <collision>
      <origin
        xyz="0 0 0"
        rpy="0 0 0" />
      <geometry>
        <mesh
          filename="package://rover/meshes/resize_rover/devide_rover/RRLH_Wheel.dae" />
      </geometry>
    </collision>
  </link>
  <joint
    name="rfl_wheel_joint"
    type="continuous">
    <origin xyz="0 0 0" rpy="0 0 0" />
    <parent
      link="rear_left_temp_link3" />
    <child
      link="rfl_wheel_link" />
    <axis
      xyz="0 1 0" />
    <limit effort="1.5" velocity="20"/>
  </joint>
  <link name='rear_right_temp_link'>
		<inertial>
            <origin xyz="0 0 0" rpy="0 0 0"/>
            <mass value="0.02" />
            <inertia ixx="2.61666666667e-05" ixy="0.0" ixz="0.0" iyy="2.61666666667e-05" iyz="0.0" izz="3.6e-05"/>
        </inertial>
        <collision>
            <origin rpy="0 0 0" xyz="0 0 0"/>
            <geometry>
                <cylinder radius="0.00000001" length="0.00000001"/>
            </geometry>
        </collision>
		<visual>
            <origin rpy="0 0 0" xyz="0 0 0"/>
            <geometry>
                <cylinder radius="0.00000001" length="0.00000001"/>
            </geometry>
        </visual>
	</link>
  <joint
  name="rfr_temp_joint"
  type="fixed">
   <origin xyz="1.3357 0.49906 0.071192" rpy="0 0 0"/>
  <parent
    link="base_link" />
  <child
    link="rear_right_temp_link" />
  <axis
    xyz="1 0 0" />
</joint>
  <link
  name="rear_right_suspension_link">
  <inertial>
    <origin
      xyz="-0.0078125 1.2678E-05 0.060941"
      rpy="0 0 0" />
    <mass
      value="0.30421" />
    <inertia
      ixx="0.00022406"
      ixy="-5.3036E-09"
      ixz="-1.2289E-08"
      iyy="0.00021285"
      iyz="-2.5969E-08"
      izz="0.00027948" />
  </inertial>
  <visual>
    <origin
      xyz="0 0 0"
      rpy="0 0 0" />
    <geometry>
      <mesh
        filename="package://rover/meshes/resize_rover/devide_rover/RRRH_Suspension.dae" />
    </geometry>
    <material
      name="">
      <color
        rgba="0.79216 0.81961 0.93333 1" />
    </material>
  </visual>
  <collision>
    <origin
      xyz="0 0 0"
      rpy="0 0 0" />
    <geometry>
      <mesh
        filename="package://rover/meshes/resize_rover/devide_rover/RRRH_Suspension.dae" />
    </geometry>
  </collision>
</link>
<joint
  name="rfr_suspension_joint"
  type="revolute">
   <origin xyz="0 0 0" rpy="0 0 0"/>
  <parent
    link="rear_right_temp_link" />
  <child
    link="rear_right_suspension_link" />
  <axis
    xyz="1 0 0" />
  <limit effort="5" velocity="6.28"  lower="-2.1" upper="2.1" />
</joint>
<link name='rear_right_temp_link2'>
  <inertial>
          <origin xyz="0 0 0" rpy="0 0 0"/>
          <mass value="0.02" />
          <inertia ixx="2.61666666667e-05" ixy="0.0" ixz="0.0" iyy="2.61666666667e-05" iyz="0.0" izz="3.6e-05"/>
      </inertial>
      <collision>
          <origin rpy="0 0 0" xyz="0 0 0"/>
          <geometry>
              <cylinder radius="0.00000001" length="0.00000001"/>
          </geometry>
      </collision>
  <visual>
          <origin rpy="0 0 0" xyz="0 0 0"/>
          <geometry>
              <cylinder radius="0.00000001" length="0.00000001"/>
          </geometry>
      </visual>
</link>
<joint
name="rfr_temp_joint2"
type="fixed">
 <origin xyz="0.0638 0.2743 -0.054" rpy="0 0 0"/>
<parent
  link="rear_right_suspension_link" />
<child
  link="rear_right_temp_link2" />
<axis
  xyz="1 0 0" />
</joint>
  <link
    name="rear_right_steering_link">
    <inertial>
      <origin
        xyz="0.0077929 0.00010875 0.060976"
        rpy="0 0 0" />
      <mass
        value="0.30421" />
      <inertia
        ixx="0.00022406"
        ixy="1.5622E-07"
        ixz="7.4851E-09"
        iyy="0.00021285"
        iyz="1.9677E-08"
        izz="0.00027948" />
    </inertial>
    <visual>
      <origin
        xyz="0 0 0"
        rpy="0 0 0" />
      <geometry>
        <mesh
        filename="package://rover/meshes/resize_rover/devide_rover/RRRH_Steering.dae" />
      </geometry>
      <material
        name="">
        <color
          rgba="0.79216 0.81961 0.93333 1" />
      </material>
    </visual>
    <collision>
      <origin
        xyz="0 0 0"
        rpy="0 0 0" />
      <geometry>
        <mesh
        filename="package://rover/meshes/resize_rover/devide_rover/RRRH_Steering.dae" />
      </geometry>
    </collision>
  </link>
  <joint
    name="rear_right_steering_joint"
    type="revolute">
    <origin xyz="0 0 0" rpy="0 0 0" />
    <parent
      link="rear_right_temp_link2" />
    <child
      link="rear_right_steering_link" />
    <axis
      xyz="0 0 1" />
    <limit effort="5" velocity="6.28"  lower="-2.1" upper="2.1" />
  </joint>
  <link name='rear_right_temp_link3'>
		<inertial>
            <origin xyz="0 0 0" rpy="0 0 0"/>
            <mass value="0.02" />
            <inertia ixx="2.61666666667e-05" ixy="0.0" ixz="0.0" iyy="2.61666666667e-05" iyz="0.0" izz="3.6e-05"/>
        </inertial>
        <collision>
            <origin rpy="0 0 0" xyz="0 0 0"/>
            <geometry>
                <cylinder radius="0.00000001" length="0.00000001"/>
            </geometry>
        </collision>
		<visual>
            <origin rpy="0 0 0" xyz="0 0 0"/>
            <geometry>
                <cylinder radius="0.00000001" length="0.00000001"/>
            </geometry>
        </visual>
	</link>
  <joint
  name="rfr_temp_joint3"
  type="fixed">
   <origin xyz="-0.0137 0.0657 -0.0259" rpy="0 0 0"/>
  <parent
    link="rear_right_steering_link" />
  <child
    link="rear_right_temp_link3" />
  <axis
    xyz="1 0 0" />
</joint>
  <link
    name="rfr_wheel_link">
    <inertial>
      <origin
        xyz="0.0016568 3.1298E-06 9.7006E-06"
        rpy="0 0 0" />
      <mass
        value="1.1361" />
      <inertia
        ixx="0.0049373"
        ixy="3.3232E-05"
        ixz="-1.942E-07"
        iyy="0.0025802"
        iyz="-1.2121E-07"
        izz="0.0025792" />
    </inertial>
    <visual>
      <origin
        xyz="0 0 0"
        rpy="0 0 0" />
      <geometry>
        <mesh
        filename="package://rover/meshes/resize_rover/devide_rover/RRRH_Wheel.dae" />
      </geometry>
      <material
        name="">
        <color
          rgba="0.79216 0.81961 0.93333 1" />
      </material>
    </visual>
    <collision>
      <origin
        xyz="0 0 0"
        rpy="0 0 0" />
      <geometry>
        <mesh
        filename="package://rover/meshes/resize_rover/devide_rover/RRRH_Wheel.dae" />
      </geometry>
    </collision>
  </link>
  <joint
    name="rfr_wheel_joint"
    type="continuous">
    <origin xyz="0 0 0" rpy="0 0 0" />
    <parent
      link="rear_right_temp_link3" />
    <child
      link="rfr_wheel_link" />
    <axis
      xyz="0 1 0" />
      <limit effort="1.5" velocity="20"/>
  </joint>

  <transmission name="front_left_suspension_trans">
    <type>transmission_interface/SimpleTransmission</type>
    <joint name="ffl_suspension_joint">
      <hardwareInterface>hardware_interface/EffortJointInterface</hardwareInterface>
    </joint>
    <actuator name="front_left_suspension_motor">
      <hardwareInterface>hardware_interface/EffortJointInterface</hardwareInterface>
      <mechanicalReduction>30</mechanicalReduction>
    </actuator>
  </transmission>
  
  <!-- Front Right Suspension Transmission -->
  <transmission name="front_right_suspension_trans">
    <type>transmission_interface/SimpleTransmission</type>
    <joint name="ffr_suspension_joint">
      <hardwareInterface>hardware_interface/EffortJointInterface</hardwareInterface>
    </joint>
    <actuator name="front_right_suspension_motor">
      <hardwareInterface>hardware_interface/EffortJointInterface</hardwareInterface>
      <mechanicalReduction>30</mechanicalReduction>
    </actuator>
  </transmission>
  
  <!-- Rear Left Suspension Transmission -->
  <transmission name="rear_left_suspension_trans">
    <type>transmission_interface/SimpleTransmission</type>
    <joint name="rfl_suspension_joint">
      <hardwareInterface>hardware_interface/EffortJointInterface</hardwareInterface>
    </joint>
    <actuator name="rear_left_suspension_motor">
      <hardwareInterface>hardware_interface/EffortJointInterface</hardwareInterface>
      <mechanicalReduction>30</mechanicalReduction>
    </actuator>
  </transmission>
  
  <!-- Rear Right Suspension Transmission -->
  <transmission name="rear_right_suspension_trans">
    <type>transmission_interface/SimpleTransmission</type>
    <joint name="rfr_suspension_joint">
      <hardwareInterface>hardware_interface/EffortJointInterface</hardwareInterface>
    </joint>
    <actuator name="rear_right_suspension_motor">
      <hardwareInterface>hardware_interface/EffortJointInterface</hardwareInterface>
      <mechanicalReduction>30</mechanicalReduction>
    </actuator>
  </transmission>

	<transmission name="front_left_steering_trans">
      <type>transmission_interface/SimpleTransmission</type>
      <joint name="front_left_steering_joint">
		<hardwareInterface>hardware_interface/PositionJointInterface</hardwareInterface>
      </joint>
	  <actuator name="front_left_steering_motor">
		<hardwareInterface>hardware_interface/PositionJointInterface</hardwareInterface>
		<mechanicalReduction>30</mechanicalReduction>
      </actuator>
	</transmission>

	<transmission name="front_right_steering_trans">
      <type>transmission_interface/SimpleTransmission</type>
      <joint name="front_right_steering_joint">
		<hardwareInterface>hardware_interface/PositionJointInterface</hardwareInterface>
      </joint>
	  <actuator name="front_right_steering_motor">
		<hardwareInterface>hardware_interface/PositionJointInterface</hardwareInterface>
		<mechanicalReduction>30</mechanicalReduction>
      </actuator>
	</transmission>

  	<transmission name="rear_left_steering_trans">
      <type>transmission_interface/SimpleTransmission</type>
      <joint name="rear_left_steering_joint">
		<hardwareInterface>hardware_interface/PositionJointInterface</hardwareInterface>
      </joint>
	  <actuator name="rear_left_steering_motor">
		<hardwareInterface>hardware_interface/PositionJointInterface</hardwareInterface>
		<mechanicalReduction>30</mechanicalReduction>
      </actuator>
	</transmission>

  	<transmission name="rear_right_steering_trans">
      <type>transmission_interface/SimpleTransmission</type>
      <joint name="rear_right_steering_joint">
		<hardwareInterface>hardware_interface/PositionJointInterface</hardwareInterface>
      </joint>
	  <actuator name="rear_right_steering_motor">
		<hardwareInterface>hardware_interface/PositionJointInterface</hardwareInterface>
		<mechanicalReduction>30</mechanicalReduction>
      </actuator>
	</transmission>

  	<transmission name="ffl_wheel_trans">
      <type>transmission_interface/SimpleTransmission</type>
      <joint name="ffl_wheel_joint">
		<hardwareInterface>hardware_interface/VelocityJointInterface</hardwareInterface>
      </joint>
	  <actuator name="ffl_wheel_motor">
		<hardwareInterface>hardware_interface/VelocityJointInterface</hardwareInterface>
		<mechanicalReduction>1</mechanicalReduction>
      </actuator>
	</transmission>
  
    	<transmission name="ffr_wheel_trans">
      <type>transmission_interface/SimpleTransmission</type>
      <joint name="ffr_wheel_joint">
		<hardwareInterface>hardware_interface/VelocityJointInterface</hardwareInterface>
      </joint>
	  <actuator name="ffr_wheel_motor">
		<hardwareInterface>hardware_interface/VelocityJointInterface</hardwareInterface>
		<mechanicalReduction>1</mechanicalReduction>
      </actuator>
	</transmission>

    	<transmission name="rfl_wheel_trans">
      <type>transmission_interface/SimpleTransmission</type>
      <joint name="rfl_wheel_joint">
		<hardwareInterface>hardware_interface/VelocityJointInterface</hardwareInterface>
      </joint>
	  <actuator name="rfl_wheel_motor">
		<hardwareInterface>hardware_interface/VelocityJointInterface</hardwareInterface>
		<mechanicalReduction>1</mechanicalReduction>
      </actuator>
	</transmission>

    	<transmission name="rfr_wheel_trans">
      <type>transmission_interface/SimpleTransmission</type>
      <joint name="rfr_wheel_joint">
		<hardwareInterface>hardware_interface/VelocityJointInterface</hardwareInterface>
      </joint>
	  <actuator name="rfr_wheel_motor">
		<hardwareInterface>hardware_interface/VelocityJointInterface</hardwareInterface>
		<mechanicalReduction>1</mechanicalReduction>
      </actuator>
	</transmission>

  <gazebo>
    <plugin name="gazebo_ros_control" filename="libgazebo_ros_control.so">
      <robotNamespace>/rover</robotNamespace>
      <robotSimType>gazebo_ros_control/DefaultRobotHWSim</robotSimType>
    </plugin>
  </gazebo>






</robot>
